<?xml version="1.0" ?>
<!-- =================================================================================== -->
<!-- |    This document was autogenerated by xacro from /ros_ws/src/panther_description/urdf/panther.urdf.xacro | -->
<!-- |    EDITING THIS FILE BY HAND IS NOT RECOMMENDED                                 | -->
<!-- =================================================================================== -->
<robot name="panther">
  <link name="base_link"/>
  <link name="chassis_link">
    <visual>
      <geometry>
        <mesh filename="package://panther_description/meshes/body_bottom.stl" scale="0.001 0.001 0.001"/>
      </geometry>
      <origin rpy=" 1.5707963267948966 0 1.5707963267948966" xyz="0 0 0"/>
      <material name="base_color">
        <color rgba="1.0 1.0 1.0 1.0"/>
      </material>
    </visual>
    <collision>
      <geometry>
        <mesh filename="package://panther_description/meshes/body_bottom.stl" scale="0.001 0.001 0.001"/>
      </geometry>
      <origin rpy=" 1.5707963267948966 0 1.5707963267948966" xyz="0 0 0"/>
    </collision>
    <inertial>
      <mass value="20"/>
      <inertia ixx="9.165e-05" ixy="5.98e-06" ixz="-1.8e-06" iyy="3.309e-05" iyz="-1.473e-05" izz="8.256e-05"/>
    </inertial>
  </link>
  <link name="cover_link">
    <inertial>
      <mass value="0.0000001"/>
      <inertia ixx="1" ixy="0" ixz="0" iyy="1" iyz="0" izz="1"/>
    </inertial>
    <visual>
      <geometry>
        <mesh filename="package://panther_description/meshes/body_top.stl" scale="0.001 0.001 0.001"/>
      </geometry>
      <origin rpy=" 1.5707963267948966 0 1.5707963267948966" xyz="0 0 0"/>
      <material name="cover_color">
        <color rgba="0.8 0.0 0.0 1.0"/>
      </material>
    </visual>
  </link>
  <joint name="base_link_to_chassis_joint" type="fixed">
    <origin rpy="0 0 0" xyz="0 0 0"/>
    <parent link="base_link"/>
    <child link="chassis_link"/>
  </joint>
  <joint name="chassis_to_cover_joint" type="fixed">
    <origin rpy="0 0 0" xyz="0 0 0"/>
    <parent link="chassis_link"/>
    <child link="cover_link"/>
  </joint>
  <gazebo reference="chassis_link">
    <material>Gazebo/White</material>
  </gazebo>
  <gazebo reference="cover_link">
    <material>Gazebo/Red</material>
  </gazebo>
  <link name="front_left_wheel_link">
    <visual>
      <geometry>
        <mesh filename="package://panther_description/meshes/wheel.stl" scale="0.001 0.001 0.001"/>
      </geometry>
      <origin rpy="0 0 1.5707963267948966" xyz="0 0 0"/>
      <material name="wheel_color">
        <color rgba="0.15 0.15 0.15 1.0"/>
      </material>
    </visual>
    <collision>
      <geometry>
        <mesh filename="package://panther_description/meshes/wheel.stl" scale="0.001 0.001 0.001"/>
      </geometry>
      <origin rpy="0 0 1.5707963267948966" xyz="0 0 0"/>
    </collision>
    <inertial>
      <mass value="0.3"/>
      <inertia ixx="9.165e-05" ixy="5.98e-06" ixz="-1.8e-06" iyy="3.309e-05" iyz="-1.473e-05" izz="8.256e-05"/>
    </inertial>
  </link>
  <joint name="front_left_wheel_joint" type="continuous">
    <parent link="chassis_link"/>
    <child link="front_left_wheel_link"/>
    <origin rpy="0 0 0" xyz="0.38 0.4 0"/>
    <axis xyz="0 1 0"/>
    <limit effort="10" velocity="10"/>
    <dynamics damping="0.0" friction="0.0"/>
  </joint>
  <transmission name="front_left_wheel_transmission" type="SimpleTransmission">
    <type>transmission_interface/SimpleTransmission</type>
    <joint name="front_left_wheel_joint">
      <hardwareInterface>hardware_interface/EffortJointInterface</hardwareInterface>
    </joint>
    <actuator name="front_left_wheel_actuator">
      <mechanicalReduction>1</mechanicalReduction>
      <hardwareInterface>hardware_interface/EffortJointInterface</hardwareInterface>
    </actuator>
  </transmission>
  <gazebo reference="front_left_wheel_link">
    <mu1 value="0.93"/>
    <mu2 value="0.2"/>
    <kp value="10000000.0"/>
    <kd value="1.0"/>
    <fdir1 value="1 0 0"/>
    <material>Gazebo/Grey</material>
  </gazebo>
  <gazebo reference="front_left_wheel_joint">
    <provideFeedback>true</provideFeedback>
  </gazebo>
  <link name="front_right_wheel_link">
    <visual>
      <geometry>
        <mesh filename="package://panther_description/meshes/wheel.stl" scale="0.001 0.001 0.001"/>
      </geometry>
      <origin rpy="0 0 1.5707963267948966" xyz="0 0 0"/>
      <material name="wheel_color">
        <color rgba="0.15 0.15 0.15 1.0"/>
      </material>
    </visual>
    <collision>
      <geometry>
        <mesh filename="package://panther_description/meshes/wheel.stl" scale="0.001 0.001 0.001"/>
      </geometry>
      <origin rpy="0 0 1.5707963267948966" xyz="0 0 0"/>
    </collision>
    <inertial>
      <mass value="0.3"/>
      <inertia ixx="9.165e-05" ixy="5.98e-06" ixz="-1.8e-06" iyy="3.309e-05" iyz="-1.473e-05" izz="8.256e-05"/>
    </inertial>
  </link>
  <joint name="front_right_wheel_joint" type="continuous">
    <parent link="chassis_link"/>
    <child link="front_right_wheel_link"/>
    <origin rpy="0 0 0" xyz="0.38 -0.4 0"/>
    <axis xyz="0 1 0"/>
    <limit effort="10" velocity="10"/>
    <dynamics damping="0.0" friction="0.0"/>
  </joint>
  <transmission name="front_right_wheel_transmission" type="SimpleTransmission">
    <type>transmission_interface/SimpleTransmission</type>
    <joint name="front_right_wheel_joint">
      <hardwareInterface>hardware_interface/EffortJointInterface</hardwareInterface>
    </joint>
    <actuator name="front_right_wheel_actuator">
      <mechanicalReduction>1</mechanicalReduction>
      <hardwareInterface>hardware_interface/EffortJointInterface</hardwareInterface>
    </actuator>
  </transmission>
  <gazebo reference="front_right_wheel_link">
    <mu1 value="0.93"/>
    <mu2 value="0.2"/>
    <kp value="10000000.0"/>
    <kd value="1.0"/>
    <fdir1 value="1 0 0"/>
    <material>Gazebo/Grey</material>
  </gazebo>
  <gazebo reference="front_right_wheel_joint">
    <provideFeedback>true</provideFeedback>
  </gazebo>
  <link name="rear_left_wheel_link">
    <visual>
      <geometry>
        <mesh filename="package://panther_description/meshes/wheel.stl" scale="0.001 0.001 0.001"/>
      </geometry>
      <origin rpy="0 0 1.5707963267948966" xyz="0 0 0"/>
      <material name="wheel_color">
        <color rgba="0.15 0.15 0.15 1.0"/>
      </material>
    </visual>
    <collision>
      <geometry>
        <mesh filename="package://panther_description/meshes/wheel.stl" scale="0.001 0.001 0.001"/>
      </geometry>
      <origin rpy="0 0 1.5707963267948966" xyz="0 0 0"/>
    </collision>
    <inertial>
      <mass value="0.3"/>
      <inertia ixx="9.165e-05" ixy="5.98e-06" ixz="-1.8e-06" iyy="3.309e-05" iyz="-1.473e-05" izz="8.256e-05"/>
    </inertial>
  </link>
  <joint name="rear_left_wheel_joint" type="continuous">
    <parent link="chassis_link"/>
    <child link="rear_left_wheel_link"/>
    <origin rpy="0 0 0" xyz="-0.38 0.4 0"/>
    <axis xyz="0 1 0"/>
    <limit effort="10" velocity="10"/>
    <dynamics damping="0.0" friction="0.0"/>
  </joint>
  <transmission name="rear_left_wheel_transmission" type="SimpleTransmission">
    <type>transmission_interface/SimpleTransmission</type>
    <joint name="rear_left_wheel_joint">
      <hardwareInterface>hardware_interface/EffortJointInterface</hardwareInterface>
    </joint>
    <actuator name="rear_left_wheel_actuator">
      <mechanicalReduction>1</mechanicalReduction>
      <hardwareInterface>hardware_interface/EffortJointInterface</hardwareInterface>
    </actuator>
  </transmission>
  <gazebo reference="rear_left_wheel_link">
    <mu1 value="0.93"/>
    <mu2 value="0.2"/>
    <kp value="10000000.0"/>
    <kd value="1.0"/>
    <fdir1 value="1 0 0"/>
    <material>Gazebo/Grey</material>
  </gazebo>
  <gazebo reference="rear_left_wheel_joint">
    <provideFeedback>true</provideFeedback>
  </gazebo>
  <link name="rear_right_wheel_link">
    <visual>
      <geometry>
        <mesh filename="package://panther_description/meshes/wheel.stl" scale="0.001 0.001 0.001"/>
      </geometry>
      <origin rpy="0 0 1.5707963267948966" xyz="0 0 0"/>
      <material name="wheel_color">
        <color rgba="0.15 0.15 0.15 1.0"/>
      </material>
    </visual>
    <collision>
      <geometry>
        <mesh filename="package://panther_description/meshes/wheel.stl" scale="0.001 0.001 0.001"/>
      </geometry>
      <origin rpy="0 0 1.5707963267948966" xyz="0 0 0"/>
    </collision>
    <inertial>
      <mass value="0.3"/>
      <inertia ixx="9.165e-05" ixy="5.98e-06" ixz="-1.8e-06" iyy="3.309e-05" iyz="-1.473e-05" izz="8.256e-05"/>
    </inertial>
  </link>
  <joint name="rear_right_wheel_joint" type="continuous">
    <parent link="chassis_link"/>
    <child link="rear_right_wheel_link"/>
    <origin rpy="0 0 0" xyz="-0.38 -0.4 0"/>
    <axis xyz="0 1 0"/>
    <limit effort="10" velocity="10"/>
    <dynamics damping="0.0" friction="0.0"/>
  </joint>
  <transmission name="rear_right_wheel_transmission" type="SimpleTransmission">
    <type>transmission_interface/SimpleTransmission</type>
    <joint name="rear_right_wheel_joint">
      <hardwareInterface>hardware_interface/EffortJointInterface</hardwareInterface>
    </joint>
    <actuator name="rear_right_wheel_actuator">
      <mechanicalReduction>1</mechanicalReduction>
      <hardwareInterface>hardware_interface/EffortJointInterface</hardwareInterface>
    </actuator>
  </transmission>
  <gazebo reference="rear_right_wheel_link">
    <mu1 value="0.93"/>
    <mu2 value="0.2"/>
    <kp value="10000000.0"/>
    <kd value="1.0"/>
    <fdir1 value="1 0 0"/>
    <material>Gazebo/Grey</material>
  </gazebo>
  <gazebo reference="rear_right_wheel_joint">
    <provideFeedback>true</provideFeedback>
  </gazebo>
  <gazebo>
    <plugin filename="libgazebo_ros_skid_steer_drive.so" name="skid_steer_drive_controller">
      <updateRate>10.0</updateRate>
      <robotBaseFrame>base_link</robotBaseFrame>
      <wheelSeparation>0.8</wheelSeparation>
      <wheelDiameter>0.2</wheelDiameter>
      <torque>10</torque>
      <leftFrontJoint>front_left_wheel_joint</leftFrontJoint>
      <rightFrontJoint>front_right_wheel_joint</rightFrontJoint>
      <leftRearJoint>rear_left_wheel_joint</leftRearJoint>
      <rightRearJoint>rear_right_wheel_joint</rightRearJoint>
      <topicName>cmd_vel</topicName>
      <commandTopic>cmd_vel</commandTopic>
      <broadcastTF>true</broadcastTF>
      <odometryTopic>odom</odometryTopic>
      <odometryFrame>odom</odometryFrame>
      <covariance_x>0.000100</covariance_x>
      <covariance_y>0.000100</covariance_y>
      <covariance_yaw>0.010000</covariance_yaw>
    </plugin>
  </gazebo>
  <gazebo>
    <plugin filename="libgazebo_ros_control.so" name="gazebo_ros_control">
      <robotNamespace>/</robotNamespace>
      <legacyModeNS>true</legacyModeNS>
    </plugin>
  </gazebo>
</robot>