<?xml version="1.0" encoding="utf-8"?>
<robot xmlns:xacro="http://www.ros.org/wiki/xacro">

  <!-- wheel defining macro -->
  <xacro:macro name="wheel" params="wheel_props common_props prefix">

    <xacro:property name="rpy" value="0 0 ${pi/2}" />
    <xacro:property name="mesh_folder" value="${wheel_props['mesh_folder']}" />
    <xacro:if value="${prefix == 'front_left'}">
      <xacro:property name="x" value="0.22" />
      <xacro:property name="y" value="${wheel_props['wheel_separation']/2}" />
      <xacro:property name="mesh" value="file://$(find panther_description)/models/panther/meshes/${mesh_folder}/wheel_a.stl" />
    </xacro:if>
    <xacro:if value="${prefix == 'front_right'}">
      <xacro:property name="x" value="0.22" />
      <xacro:property name="y" value="-${wheel_props['wheel_separation']/2}" />
      <xacro:property name="mesh" value="file://$(find panther_description)/models/panther/meshes/${mesh_folder}/wheel_b.stl" />
    </xacro:if>
    <xacro:if value="${prefix == 'rear_left'}">
      <xacro:property name="x" value="-0.22" />
      <xacro:property name="y" value="${wheel_props['wheel_separation']/2}" />
      <xacro:property name="mesh" value="file://$(find panther_description)/models/panther/meshes/${mesh_folder}/wheel_a.stl" />
    </xacro:if>
    <xacro:if value="${prefix == 'rear_right'}">
      <xacro:property name="x" value="-0.22" />
      <xacro:property name="y" value="-${wheel_props['wheel_separation']/2}" />
      <xacro:property name="mesh" value="file://$(find panther_description)/models/panther/meshes/${mesh_folder}/wheel_b.stl" />
    </xacro:if>


    <link name="${prefix}_wheel_link">
       <visual>
        <geometry>
            <mesh filename="${mesh}" scale="1 1 1" />
        </geometry>
        <origin xyz="0 0 0" rpy="${rpy}"/>
        <material name="${wheel_props['color']}"/>
      </visual>

      <collision>
        <geometry>
            <mesh filename="file://$(find panther_description)/models/panther/meshes/${mesh_folder}/collision.stl" scale="1 1 1" />
        </geometry>
        <origin xyz="0 0 0" rpy="${rpy}" />
      </collision>

      <inertial>
          <mass value="${wheel_props['mass']}" />
          <inertia ixx="${wheel_props['inertia']['ixx']}"
                   ixy="${wheel_props['inertia']['ixy']}"
                   ixz="${wheel_props['inertia']['ixz']}"
                   iyy="${wheel_props['inertia']['iyy']}"
                   iyz="${wheel_props['inertia']['iyz']}"
                   izz="${wheel_props['inertia']['izz']}" />
      </inertial>
    </link>

    <joint name="${prefix}_wheel_joint" type="continuous">
      <parent link="body_link" />
      <child link="${prefix}_wheel_link" />
      <origin xyz="${x} ${y} 0" rpy="0 0 0" />
      <axis xyz="0 1 0" />

      <limit effort="${common_props['motors']['max_torque']}"
             velocity="${common_props['motors']['max_velocity']}" />

      <dynamics damping="${common_props['motors']['joint_damping']}"
                friction="${common_props['motors']['joint_friction']}"/>
    </joint>

    <gazebo reference="${prefix}_wheel_link">
      <mu1 value="${wheel_props['lateral_friction']}" />
      <mu2 value="${wheel_props['spinning_friction']}" />
      <kp value="${wheel_props['contact_stiffness']}" />
      <kd value="${wheel_props['contact_damping']}" />
      <fdir1 value="1 0 0"/>
      <material>Gazebo/${wheel_props['color']}</material>
    </gazebo>
    
  </xacro:macro>

</robot>