<?xml version="1.0" ?>
<!-- =================================================================================== -->
<!-- |    This document was autogenerated by xacro from panther.urdf.xacro             | -->
<!-- |    EDITING THIS FILE BY HAND IS NOT RECOMMENDED                                 | -->
<!-- =================================================================================== -->
<robot name="panther">
  <link name="base_link"/>
  <joint name="base_link_to_body_link_joint" type="fixed">
    <origin rpy="0.0 0.0 0.0" xyz="0.0 0.0 0.1825"/>
    <parent link="base_link"/>
    <child link="body_link"/>
  </joint>
  <link name="body_link">
    <visual>
      <geometry>
        <mesh filename="file:///home/developer/ros_ws/src/panther_description/meshes/body.dae"/>
      </geometry>
      <origin rpy="0.0 0.0 0.0" xyz="0.0 0.0 0.0"/>
    </visual>
    <collision>
      <geometry>
        <mesh filename="file:///home/developer/ros_ws/src/panther_description/meshes/body_collision.stl"/>
      </geometry>
      <origin rpy="0.0 0.0 0.0" xyz="0.0 0.0 0.0"/>
    </collision>
    <inertial>
      <origin rpy="0.0 0.0 0.0" xyz="-0.008 0.01 0.029"/>
      <mass value="43.0"/>
      <inertia ixx="2.630036" ixy="-0.023480" ixz="0.052320" iyy="2.463509" iyz="0.009337" izz="4.611945"/>
    </inertial>
  </link>
  <joint name="body_link_to_imu_link_joint" type="fixed">
    <origin rpy="0.0 0.0 -1.57" xyz="0.169 0.025 0.092"/>
    <parent link="body_link"/>
    <child link="imu_link"/>
  </joint>
  <link name="imu_link"/>
  <joint name="body_link_front_light_link_joint" type="fixed">
    <origin rpy="0.0 0.0 0.0" xyz="0.362 0.0 0.0"/>
    <parent link="body_link"/>
    <child link="front_light_link"/>
  </joint>
  <link name="front_light_link"/>
  <joint name="body_link_to_rear_light_link_joint" type="fixed">
    <origin rpy="0.0 0.0 3.141592653589793" xyz="-0.362 0.0 0.0"/>
    <parent link="body_link"/>
    <child link="rear_light_link"/>
  </joint>
  <link name="rear_light_link"/>
  <joint name="body_link_to_cover_link_joint" type="fixed">
    <origin rpy="0.0 0.0 0.0" xyz="0.0 0.0 0.1715"/>
    <parent link="body_link"/>
    <child link="cover_link"/>
  </joint>
  <link name="cover_link"/>
  <gazebo>
    <plugin filename="libhector_gazebo_ros_imu.so" name="imu_controller">
      <robotNamespace>/</robotNamespace>
      <updateRate>100.0</updateRate>
      <bodyName>imu_link</bodyName>
      <topicName>imu</topicName>
      <accelDrift>0.000398286 0.000398286 0.000398286</accelDrift>
      <accelGaussianNoise>0.0027467999999999998 0.0027467999999999998 0.0027467999999999998</accelGaussianNoise>
      <rateDrift>7.330382858376184e-05 7.330382858376184e-05 7.330382858376184e-05</rateDrift>
      <rateGaussianNoise>0.0016580627893946131 0.0016580627893946131 0.0016580627893946131</rateGaussianNoise>
    </plugin>
  </gazebo>
  <joint name="fl_joint" type="continuous">
    <parent link="body_link"/>
    <child link="fl_wheel_link"/>
    <origin rpy="0.0 0.0 0.0" xyz="0.22 0.3485 0.0"/>
    <axis xyz="0.0 1.0 0.0"/>
    <limit effort="34.5" velocity="2.0"/>
    <dynamics damping="0.01" friction="0.01"/>
  </joint>
  <link name="fl_wheel_link">
    <visual>
      <geometry>
        <mesh filename="file:///home/developer/ros_ws/src/panther_description/meshes/WH01/fl_wheel.dae"/>
      </geometry>
      <origin rpy="0.0 0.0 0.0" xyz="0.0 0.0 0.0"/>
    </visual>
    <collision>
      <geometry>
        <mesh filename="file:///home/developer/ros_ws/src/panther_description/meshes/WH01/collision.stl"/>
      </geometry>
      <origin rpy="0.0 0.0 0.0" xyz="0.0 0.0 0.0"/>
    </collision>
    <inertial>
      <origin rpy="0.0 0.0 0.0" xyz="0.0 0.0 0.0"/>
      <mass value="3.0"/>
      <inertia ixx="0.02251" ixy="0.0" ixz="0.0" iyy="0.03485" iyz="0.0" izz="0.02251"/>
    </inertial>
  </link>
  <transmission name="fl_transmission" type="SimpleTransmission">
    <type>transmission_interface/SimpleTransmission</type>
    <joint name="fl_joint">
      <hardwareInterface>hardware_interface/EffortJointInterface</hardwareInterface>
    </joint>
    <actuator name="fl_actuator">
      <mechanicalReduction>1</mechanicalReduction>
      <hardwareInterface>hardware_interface/EffortJointInterface</hardwareInterface>
    </actuator>
  </transmission>
  <gazebo reference="fl_joint">
    <provideFeedback>true</provideFeedback>
  </gazebo>
  <joint name="fr_joint" type="continuous">
    <parent link="body_link"/>
    <child link="fr_wheel_link"/>
    <origin rpy="0.0 0.0 0.0" xyz="0.22 -0.3485 0.0"/>
    <axis xyz="0.0 1.0 0.0"/>
    <limit effort="34.5" velocity="2.0"/>
    <dynamics damping="0.01" friction="0.01"/>
  </joint>
  <link name="fr_wheel_link">
    <visual>
      <geometry>
        <mesh filename="file:///home/developer/ros_ws/src/panther_description/meshes/WH01/fr_wheel.dae"/>
      </geometry>
      <origin rpy="0.0 0.0 0.0" xyz="0.0 0.0 0.0"/>
    </visual>
    <collision>
      <geometry>
        <mesh filename="file:///home/developer/ros_ws/src/panther_description/meshes/WH01/collision.stl"/>
      </geometry>
      <origin rpy="0.0 0.0 0.0" xyz="0.0 0.0 0.0"/>
    </collision>
    <inertial>
      <origin rpy="0.0 0.0 0.0" xyz="0.0 -0.0 0.0"/>
      <mass value="3.0"/>
      <inertia ixx="0.02251" ixy="0.0" ixz="0.0" iyy="0.03485" iyz="0.0" izz="0.02251"/>
    </inertial>
  </link>
  <transmission name="fr_transmission" type="SimpleTransmission">
    <type>transmission_interface/SimpleTransmission</type>
    <joint name="fr_joint">
      <hardwareInterface>hardware_interface/EffortJointInterface</hardwareInterface>
    </joint>
    <actuator name="fr_actuator">
      <mechanicalReduction>1</mechanicalReduction>
      <hardwareInterface>hardware_interface/EffortJointInterface</hardwareInterface>
    </actuator>
  </transmission>
  <gazebo reference="fr_joint">
    <provideFeedback>true</provideFeedback>
  </gazebo>
  <joint name="rl_joint" type="continuous">
    <parent link="body_link"/>
    <child link="rl_wheel_link"/>
    <origin rpy="0.0 0.0 0.0" xyz="-0.22 0.3485 0.0"/>
    <axis xyz="0.0 1.0 0.0"/>
    <limit effort="34.5" velocity="2.0"/>
    <dynamics damping="0.01" friction="0.01"/>
  </joint>
  <link name="rl_wheel_link">
    <visual>
      <geometry>
        <mesh filename="file:///home/developer/ros_ws/src/panther_description/meshes/WH01/rl_wheel.dae"/>
      </geometry>
      <origin rpy="0.0 0.0 0.0" xyz="0.0 0.0 0.0"/>
    </visual>
    <collision>
      <geometry>
        <mesh filename="file:///home/developer/ros_ws/src/panther_description/meshes/WH01/collision.stl"/>
      </geometry>
      <origin rpy="0.0 0.0 0.0" xyz="0.0 0.0 0.0"/>
    </collision>
    <inertial>
      <origin rpy="0.0 0.0 0.0" xyz="0.0 0.0 0.0"/>
      <mass value="3.0"/>
      <inertia ixx="0.02251" ixy="0.0" ixz="0.0" iyy="0.03485" iyz="0.0" izz="0.02251"/>
    </inertial>
  </link>
  <transmission name="rl_transmission" type="SimpleTransmission">
    <type>transmission_interface/SimpleTransmission</type>
    <joint name="rl_joint">
      <hardwareInterface>hardware_interface/EffortJointInterface</hardwareInterface>
    </joint>
    <actuator name="rl_actuator">
      <mechanicalReduction>1</mechanicalReduction>
      <hardwareInterface>hardware_interface/EffortJointInterface</hardwareInterface>
    </actuator>
  </transmission>
  <gazebo reference="rl_joint">
    <provideFeedback>true</provideFeedback>
  </gazebo>
  <joint name="rr_joint" type="continuous">
    <parent link="body_link"/>
    <child link="rr_wheel_link"/>
    <origin rpy="0.0 0.0 0.0" xyz="-0.22 -0.3485 0.0"/>
    <axis xyz="0.0 1.0 0.0"/>
    <limit effort="34.5" velocity="2.0"/>
    <dynamics damping="0.01" friction="0.01"/>
  </joint>
  <link name="rr_wheel_link">
    <visual>
      <geometry>
        <mesh filename="file:///home/developer/ros_ws/src/panther_description/meshes/WH01/rr_wheel.dae"/>
      </geometry>
      <origin rpy="0.0 0.0 0.0" xyz="0.0 0.0 0.0"/>
    </visual>
    <collision>
      <geometry>
        <mesh filename="file:///home/developer/ros_ws/src/panther_description/meshes/WH01/collision.stl"/>
      </geometry>
      <origin rpy="0.0 0.0 0.0" xyz="0.0 0.0 0.0"/>
    </collision>
    <inertial>
      <origin rpy="0.0 0.0 0.0" xyz="0.0 -0.0 0.0"/>
      <mass value="3.0"/>
      <inertia ixx="0.02251" ixy="0.0" ixz="0.0" iyy="0.03485" iyz="0.0" izz="0.02251"/>
    </inertial>
  </link>
  <transmission name="rr_transmission" type="SimpleTransmission">
    <type>transmission_interface/SimpleTransmission</type>
    <joint name="rr_joint">
      <hardwareInterface>hardware_interface/EffortJointInterface</hardwareInterface>
    </joint>
    <actuator name="rr_actuator">
      <mechanicalReduction>1</mechanicalReduction>
      <hardwareInterface>hardware_interface/EffortJointInterface</hardwareInterface>
    </actuator>
  </transmission>
  <gazebo reference="rr_joint">
    <provideFeedback>true</provideFeedback>
  </gazebo>
  <gazebo>
    <plugin filename="libgazebo_ros_control.so" name="gazebo_ros_control">
      <robotNamespace>/</robotNamespace>
      <legacyModeNS>true</legacyModeNS>
    </plugin>
  </gazebo>
  <gazebo>
    <plugin filename="libgazebo_ros_skid_steer_drive.so" name="skid_steer_drive_controller">
      <updateRate>20.0</updateRate>
      <robotBaseFrame>base_link</robotBaseFrame>
      <wheelSeparation>0.697</wheelSeparation>
      <wheelDiameter>0.365</wheelDiameter>
      <torque>34.5</torque>
      <leftFrontJoint>fl_joint</leftFrontJoint>
      <rightFrontJoint>fr_joint</rightFrontJoint>
      <leftRearJoint>rl_joint</leftRearJoint>
      <rightRearJoint>rr_joint</rightRearJoint>
      <topicName>cmd_vel</topicName>
      <commandTopic>cmd_vel</commandTopic>
      <broadcastTF>true</broadcastTF>
      <odometryTopic>odom</odometryTopic>
      <odometryFrame>odom</odometryFrame>
    </plugin>
  </gazebo>
</robot>

